Config file ../snakemake/config/config.yaml is extended by additional config specified via the command line.
Building DAG of jobs...
Using shell: /bin/bash
Provided cores: 2
Rules claiming more threads will be scaled down.
Conda environments: ignored
Job stats:
job           count
----------  -------
MDScluster        1
total             1

Resources before job selection: {'_cores': 2, '_nodes': 9223372036854775807}
Ready jobs (1)
Select jobs to execute...
Selected jobs (1)
Resources after job selection: {'_cores': 1, '_nodes': 9223372036854775806}

[Tue Dec 12 16:37:21 2023]
rule MDScluster:
    input: res/1distanceMatrixFormation.done
    output: res/2MDS+cluster.done
    jobid: 0
    reason: Missing output files: res/2MDS+cluster.done
    resources: tmpdir=/var/folders/qx/45c8cdmd6rx_np70td6hmvhr0000gn/T

Full Traceback (most recent call last):
  File "/Users/windsorkoh/mambaforge/lib/python3.10/site-packages/snakemake/executors/__init__.py", line 2656, in run_wrapper
    run(
  File "/Users/windsorkoh/Desktop/git/snakemake/workflow/Snakefile", line 44, in __rule_MDScluster
    "res/6faster.done",
  File "/Users/windsorkoh/mambaforge/lib/python3.10/site-packages/snakemake/shell.py", line 294, in __new__
    raise sp.CalledProcessError(retcode, cmd)
subprocess.CalledProcessError: Command 'set -euo pipefail;  conda activate --file envs/2MDScluster.yaml; python workflow/scripts/2MDS+cluster.py /Users/windsorkoh/Desktop/git/snakemake/data/CLUSTER0/distancearrays' returned non-zero exit status 1.

[Tue Dec 12 16:37:21 2023]
Error in rule MDScluster:
    jobid: 0
    input: res/1distanceMatrixFormation.done
    output: res/2MDS+cluster.done
    conda-env: /Users/windsorkoh/Desktop/git/snakemake/.snakemake/conda/d801188709ce28ada455d5d981e69923_
    shell:
        conda activate --file envs/2MDScluster.yaml; python workflow/scripts/2MDS+cluster.py /Users/windsorkoh/Desktop/git/snakemake/data/CLUSTER0/distancearrays
        (one of the commands exited with non-zero exit code; note that snakemake uses bash strict mode!)

Full Traceback (most recent call last):
  File "/Users/windsorkoh/mambaforge/lib/python3.10/site-packages/snakemake/executors/__init__.py", line 2656, in run_wrapper
    run(
  File "/Users/windsorkoh/Desktop/git/snakemake/workflow/Snakefile", line 44, in __rule_MDScluster
    "res/6faster.done",
  File "/Users/windsorkoh/mambaforge/lib/python3.10/site-packages/snakemake/shell.py", line 294, in __new__
    raise sp.CalledProcessError(retcode, cmd)
subprocess.CalledProcessError: Command 'set -euo pipefail;  conda activate --file envs/2MDScluster.yaml; python workflow/scripts/2MDS+cluster.py /Users/windsorkoh/Desktop/git/snakemake/data/CLUSTER0/distancearrays' returned non-zero exit status 1.

During handling of the above exception, another exception occurred:

Traceback (most recent call last):
  File "/Users/windsorkoh/mambaforge/lib/python3.10/site-packages/snakemake/executors/__init__.py", line 715, in _callback
    raise ex
  File "/Users/windsorkoh/mambaforge/lib/python3.10/concurrent/futures/thread.py", line 58, in run
    result = self.fn(*self.args, **self.kwargs)
  File "/Users/windsorkoh/mambaforge/lib/python3.10/site-packages/snakemake/executors/__init__.py", line 699, in cached_or_run
    run_func(*args)
  File "/Users/windsorkoh/mambaforge/lib/python3.10/site-packages/snakemake/executors/__init__.py", line 2692, in run_wrapper
    raise RuleException(
snakemake.exceptions.RuleException: CalledProcessError in file /Users/windsorkoh/Desktop/git/snakemake/workflow/Snakefile, line 18:
Command 'set -euo pipefail;  conda activate --file envs/2MDScluster.yaml; python workflow/scripts/2MDS+cluster.py /Users/windsorkoh/Desktop/git/snakemake/data/CLUSTER0/distancearrays' returned non-zero exit status 1.
  File "/Users/windsorkoh/Desktop/git/snakemake/workflow/Snakefile", line 18, in __rule_MDScluster

RuleException:
CalledProcessError in file /Users/windsorkoh/Desktop/git/snakemake/workflow/Snakefile, line 18:
Command 'set -euo pipefail;  conda activate --file envs/2MDScluster.yaml; python workflow/scripts/2MDS+cluster.py /Users/windsorkoh/Desktop/git/snakemake/data/CLUSTER0/distancearrays' returned non-zero exit status 1.
  File "/Users/windsorkoh/Desktop/git/snakemake/workflow/Snakefile", line 18, in __rule_MDScluster
  File "/Users/windsorkoh/mambaforge/lib/python3.10/concurrent/futures/thread.py", line 58, in run
Shutting down, this might take some time.
Exiting because a job execution failed. Look above for error message
Complete log: .snakemake/log/2023-12-12T163721.237937.snakemake.log
unlocking
removing lock
removing lock
removed all locks
